Workbook

Sheet START HERE
B2: Singapore MDW Total Cost of Ownership (TCO) Planner 2026
B3: A planning tool to estimate the full cost of employing a Migrant Domestic Worker — NOT legal/immigration advice.
B5: WHAT THIS WORKBOOK DOES
B6: • PROFILE & INPUTS — capture helper type, salary, levy, agency fees, insurance, medical, and other costs.
B7: • COST CALCULATOR — breaks down one-off vs recurring costs with transparent formulas.
B8: • MONTHLY / YEARLY TCO — summarises first-year total, ongoing annual cost, and monthly equivalent.
B9: • ACTION PLAN — checklist of requirements, timelines, and budgeting steps.
B11: HOW TO USE — 3 STEPS
B12: STEP 1 · Go to PROFILE & INPUTS. Fill in your arrangement details and cost assumptions.
B13: STEP 2 · Review COST CALCULATOR and MONTHLY / YEARLY TCO. Adjust inputs to see impact.
B14: STEP 3 · Use ACTION PLAN to track requirements and budgeting milestones.
B16: WHAT IS OFFICIAL vs MARKET ESTIMATE vs PLANNING ASSUMPTION vs USER INPUT
... B25: Yellow = editable input · Green = auto-calculated · Do not type into green cells.

Sheet PROFILE & INPUTS
B2: STEP 1 · YOUR MDW ARRANGEMENT & COST ASSUMPTIONS
B3: Fill in the yellow cells. Green cells calculate automatically.
B5: HELPER PROFILE
B6: Helper type (New / Transfer / Renewal) | C6: New
B7: Source country
B8: Monthly salary (S$) | C8: 600
B9: Rest day compensation (if no rest day, S$/month) | C9: 0
B10: Food allowance / groceries per month (S$) | C10: 250
B11: Transport allowance per month (S$) | C11: 50
B12: Phone / data allowance per month (S$) | C12: 30
B13: Toiletries / personal care per month (S$) | C13: 40
B14: Annual leave pay (if not given as days off, S$) | C14: 0
B15: Performance bonus / 13th month (S$, annual) | C15: 0
B17: MOM OFFICIAL COSTS (verify on MOM website)
B18: Monthly levy (S$) — Standard / Concession | C18: 300 | D18: Verify current rate on MOM website
B19: Levy concession applicable? | C19: No | D19: Verify current rate on MOM website
B20: Security bond (S$) — MOM requirement | C20: 5000 | D20: Verify current rate on MOM website
B21: Work permit application fee (S$) — MOM | C21: 35 | D21: Verify current rate on MOM website
B22: Work permit issuance fee (S$) — MOM | C22: 35 | D22: Verify current rate on MOM website
B23: Medical examination (S$) — MOM required (6-monthly) | C23: 80 | D23: Verify current rate on MOM website
B24: Settling-in Programme (SIP) — one-off (S$) | C24: 75 | D24: Verify current rate on MOM website
B26: AGENCY & INSURANCE (market estimates — vary by provider)
B27: Agency placement fee (S$) — one-off | C27: 2500
B28: Agency fee includes: | C28: Placement, medical, SIP, bond processing
B29: Insurance — Medical (S$) | C29: 60000
B30: Insurance — Personal Accident (S$) | C30: 60000
B31: Insurance coverage label | C31: Official MOM requirement
B32: Insurance premium — annual (S$) — Market estimate | C32: 260
B33: Insurance premium label | C33: Market estimate
B34: OTHER RECURRING / ONE-OFF COSTS (planning assumptions) | C34: No
B35: Home leave / annual trip (S$, annual) | C35: 0
B36: Replacement maid cost (S$, if needed) | C36: 0
B37: Additional training / courses (S$) | C37: 0
B38: Miscellaneous / buffer per month (S$) | C38: 50
B40: HOUSEHOLD CONTEXT
B41: Employer household monthly income (S$) | C41: 0
B42: Number of dependents (children/elderly) | C42: 0
B43: Current maid? (Yes/No) | C43: No
B44: If yes, months remaining on current contract | C44: 0

Sheet COST CALCULATOR
B2: COST CALCULATOR — TRANSPARENT BREAKDOWN
B3: All formulas reference PROFILE & INPUTS. Green = calculated. Do not edit.
B5: MONTHLY RECURRING COSTS
B6: Item | C6: Monthly (S$) | D6: Annual (S$) | E6: Source Type
B7: Monthly salary | C7: ='PROFILE & INPUTS'!C8 -> 0 | D7: =C7*12 -> 0 | E7: User input / Market estimate
B8: Rest day compensation | C8: ='PROFILE & INPUTS'!C9 -> 0 | D8: =C8*12 -> 0 | E8: User input / Market estimate
B9: Monthly levy | C9: ='PROFILE & INPUTS'!C19 -> 0 | D9: =C9*12 -> 0 | E9: Official (MOM)
B10: Food allowance | C10: ='PROFILE & INPUTS'!C10 -> 0 | D10: =C10*12 -> 0 | E10: Planning assumption
B11: Transport allowance | C11: ='PROFILE & INPUTS'!C11 -> 0 | D11: =C11*12 -> 0 | E11: Planning assumption
B12: Phone / data allowance | C12: ='PROFILE & INPUTS'!C12 -> 0 | D12: =C12*12 -> 0 | E12: Planning assumption
B13: Toiletries / personal care | C13: ='PROFILE & INPUTS'!C13 -> 0 | D13: =C13*12 -> 0 | E13: Planning assumption
B14: Insurance premium (annual ÷ 12) | C14: =('PROFILE & INPUTS'!C34)/12 -> 0 | D14: =C14*12 -> 0 | E14: Market estimate
B15: Miscellaneous / buffer | C15: ='PROFILE & INPUTS'!C42 -> 0 | D15: =C15*12 -> 0 | E15: Planning assumption
B16: TOTAL MONTHLY RECURRING | C16: =SUM(C7:C15) -> 0 | D16: =SUM(D7:D15) -> 0
B18: ONE-OFF / FIRST-YEAR COSTS
B19: Item | C19: Amount (S$) | D19: Source Type
B20: Agency placement fee | C20: ='PROFILE & INPUTS'!C28 -> 0 | D20: Market estimate
B21: Security bond (refundable) | C21: ='PROFILE & INPUTS'!C21 -> 0 | D21: Official (MOM)
B22: Work permit application fee | C22: ='PROFILE & INPUTS'!C22 -> 0 | D22: Official (MOM)
B23: Work permit issuance fee | C23: ='PROFILE & INPUTS'!C23 -> 0 | D23: Official (MOM)
B24: Medical examination (first) | C24: ='PROFILE & INPUTS'!C24 -> 0 | D24: Official (MOM)
B25: Settling-in Programme (SIP) | C25: ='PROFILE & INPUTS'!C25 -> 0 | D25: Official (MOM)
B26: Insurance first-year premium | C26: ='PROFILE & INPUTS'!C34 -> 0 | D26: Market estimate
B27: Agency loan interest / admin fee | C27: ='PROFILE & INPUTS'!C39 -> 0 | D27: Market estimate
B28: Home leave / annual trip (first year) | C28: ='PROFILE & INPUTS'!C40 -> 0 | D28: Planning assumption
B29: Replacement maid cost (if applicable) | C29: ='PROFILE & INPUTS'!C41 -> 0 | D29: Planning assumption
B30: Additional training / courses | C30: ='PROFILE & INPUTS'!C42 -> 0 | D30: Planning assumption
B31: TOTAL ONE-OFF / FIRST-YEAR | C31: =SUM(C20:C30) -> 0
B33: ANNUAL RECURRING FROM YEAR 2 ONWARDS
B34: Item | C34: Annual (S$) | D34: Source Type
B35: Annual recurring from monthly costs | C35: =[object Object] -> 0 | D35: Calculated
B36: Medical examination (6-monthly × 2) | C36: =[object Object] -> 0 | D36: Official (MOM)
B37: Insurance renewal (annual) | C37: ='PROFILE & INPUTS'!C34 -> 0 | D37: Market estimate
B38: Home leave / annual trip | C38: ='PROFILE & INPUTS'!C40 -> 0 | D38: Planning assumption
B39: Performance bonus / 13th month | C39: ='PROFILE & INPUTS'!C15 -> 0 | D39: User input / Market estimate
B40: Additional training / courses | C40: ='PROFILE & INPUTS'!C42 -> 0 | D40: Planning assumption
B41: TOTAL ANNUAL RECURRING (Year 2+) | C41: =SUM(C35:C40) -> 0
B43: PLACEMENT LOAN BREAKDOWN (if applicable — not statutory)
B44: Item | C44: Amount (S$) | D44: Notes
B45: Agency / placement fee (total) | C45: ='PROFILE & INPUTS'!C28 -> 0 | D45: Market estimate
...

Sheet MONTHLY YEARLY TCO
B2: TOTAL COST OF OWNERSHIP SUMMARY
B3: Auto-calculated from COST CALCULATOR and PROFILE & INPUTS.
B5: FIRST YEAR TCO
B6: Total one-off / first-year costs | C6: ='COST CALCULATOR'!C31 -> 0 | D6: One-off
B7: Total monthly recurring × 12 | C7: ='COST CALCULATOR'!D16 -> 0 | D7: Recurring
B8: FIRST-YEAR TOTAL | C8: =C6+C7 -> 0 | D8: Combined
B10: ONGOING ANNUAL TCO (Year 2+)
B11: Total annual recurring (Year 2+) | C11: ='COST CALCULATOR'!C41 -> 0 | D11: Recurring
B12: ONGOING ANNUAL TOTAL | C12: =C11 -> 0 | D12: Combined
B14: MONTHLY EQUIVALENT
B15: First-year monthly equivalent (Total ÷ 12) | C15: =C8/12 -> 0
B16: Ongoing monthly equivalent (Annual ÷ 12) | C16: =C12/12 -> 0
B18: AFFORDABILITY CHECK
B19: Household monthly income | C19: ='PROFILE & INPUTS'!C42 -> 0
B20: First-year TCO as % of annual income | C20: =IF('PROFILE & INPUTS'!C42=0,0,C8/('PROFILE & INPUTS'!C42*12)) -> 0
B21: Ongoing monthly TCO as % of monthly income | C21: =IF('PROFILE & INPUTS'!C42=0,0,C13/'PROFILE & INPUTS'!C42) -> 0
B23: KEY ASSUMPTIONS & SENSITIVITY
B24: • Levy concession reduces monthly levy from $300 to $60 (check MOM eligibility).
B25: • Security bond ($5,000) is refundable if no violations; not a "cost" but cash flow.
B26: • Salary range typically $550–$750 depending on experience and country.
B27: • Agency fees range $1,500–$3,500; compare before signing.
B28: • Insurance: MOM minimum $60,000 medical + $60,000 personal accident per year; premiums vary.
B29: • 6-monthly medical exam required by MOM (cost ~$80 each).
B30: • Placement loan is NOT a statutory requirement; it is a commercial arrangement between employer and agency.

Sheet ACTION PLAN
B2: ACTION PLAN — REQUIREMENTS & BUDGETING
B3: Track your progress. Yellow = editable. Green = auto-calculated.
B5: # | C5: Action / Requirement | D5: Timing / Deadline | E5: Priority | F5: Status | G5: Cost Impact (S$) | H5: Notes / Links
B6: 1 | C6: Confirm MOM eligibility (employer income, household needs) | D6: Before starting | E6: High | G6: 0 | H6: MOM website: FDW eligibility
B7: 2 | C7: Compare 3+ agencies (fees, services, reviews) | D7: 1-2 months before | E7: High | G7: 0 | H7: Check MOM licensed agency list
B8: 3 | C8: Budget for first-year TCO (see MONTHLY / YEARLY TCO) | D8: Before signing | E8: High | G8: ='MONTHLY YEARLY TCO'!C8 -> 0 | H8: First-year total
B9: 4 | C9: Prepare security bond $5,000 (banker's guarantee or insurance) | D9: Before WP application | E9: High | G9: 5000 | H9: Refundable if no breach
B10: 5 | C10: Arrange medical exam for helper (pre-employment) | D10: Before arrival | E10: High | G10: ='PROFILE & INPUTS'!C24 -> 0 | H10: MOM-approved clinic
B11: 6 | C11: Enrol helper in Settling-in Programme (SIP) | D11: Within 3 days of arrival | E11: High | G11: ='PROFILE & INPUTS'!C25 -> 0 | H11: MOM mandatory
B12: 7 | C12: Purchase insurance (medical $60k + personal accident $60k min) | D12: Before WP issuance | E12: High | G12: ='PROFILE & INPUTS'!C34 -> 0 | H12: MOM minimum coverage
B13: 8 | C13: Apply for Work Permit (online via MOM) | D13: After helper arrival | E13: High | G13: ='PROFILE & INPUTS'!C22+'PROFILE & INPUTS'!C23 -> 0 | H13: WP application + issuance fee
B14: 9 | C14: Set up GIRO for monthly levy payment | D14: Upon WP approval | E14: High | G14: ='PROFILE & INPUTS'!C19 -> 0 | H14: Monthly levy auto-deduction
B15: 10 | C15: Prepare helper's room / living arrangements | D15: Before arrival | E15: Medium | G15: 0 | H15: MOM housing standards
B16: 11 | C16: Purchase food, toiletries, phone plan for helper | D16: First week | E16: Medium | G16: ='PROFILE & INPUTS'!C10+'PROFILE & INPUTS'!C11+'PROFILE & INPUTS'!C12+'PROFILE & INPUTS'!C13 -> 0 | H16: Monthly recurring items
B17: 12 | C17: Schedule 6-monthly medical exams | D17: Every 6 months | E17: Medium | G17: ='PROFILE & INPUTS'!C24*2 -> 0 | H17: MOM requirement
B18: 13 | C18: Renew insurance annually | D18: Annually | E18: Medium | G18: ='PROFILE & INPUTS'!C34 -> 0 | H18: Before policy expiry
B19: 14 | C19: Plan for home leave / annual trip (if applicable) | D19: Annually | E19: Low | G19: ='PROFILE & INPUTS'!C40 -> 0 | H19: Budget in advance
B20: 15 | C20: Review contract & salary at renewal (2-year cycle) | D20: Month 22-24 | E20: Medium | G20: 0 | H20: Negotiate if needed
B21: 16 | C21: Emergency fund for replacement / repatriation | D21: Ongoing | E21: Low | G21: ='PROFILE & INPUTS'!C41 -> 0 | H21: Buffer for unexpected
B22: 17 | C22: Review placement loan terms (if any) — not statutory | D22: Before signing | E22: Medium | G22: 0 | H22: See COST CALCULATOR placement loan breakdown
B25: SUMMARY
B26: Total actions | C26: =COUNTA(C6:C22) -> 0
B27: High priority | C27: =COUNTIF(E6:E22,"High") -> 0
B28: Not Started | C28: =COUNTIF(F6:F22,"Not Started") -> 0
B29: In Progress | C29: =COUNTIF(F6:F22,"In Progress") -> 0
B30: Done | C30: =COUNTIF(F6:F22,"Done") -> 0
B31: Total cost impact (high priority) | C31: =SUMIF(E6:E22,"High",G6:G22) -> 0
